Workbook

Sheet Main Data
A1: Produksi Pakan Tiap Provinsi di Indonesia
A2: Produk | B2: Provinsi | C2: Total Produksi (ton) | D2: Tahun | E2: Tabel Bantu | F2: Harga produk per kg | G2: Total Harga Produk | H2: Banyaknya pakan per ton produk (kg) | I2: Harga pakan per kg | J2: Total Banyak Pakan | K2: Total Harga Pakan | L2: Laba kotor
A3: Daging Itik | B3: JAWA TIMUR | C3: 47068.84 | D3: 2021 | E3: =RAND() -> 0.78466217 | F3: 50000 | G3: =(C3*1000)*F3 -> 2353442000000 | H3: 26 | I3: 9800 | J3: =H3*C3 -> 1223789.8 | K3: =J3*I3 -> 1.199314e+10 | L3: =G3-K3 -> 2341448859568
A4: Daging Ayam | B4: GORONTALO | C4: 2728.33 | D4: 2021 | E4: =RAND() -> 0.12290663 | F4: 34000 | G4: =(C4*1000)*F4 -> 92763220000 | H4: 21 | I4: 9000 | J4: =H4*C4 -> 57294.93 | K4: =J4*I4 -> 515654370 | L4: =G4-K4 -> 92247565630
A5: Daging Kambing | B5: BENGKULU | C5: 176.23 | D5: 2022 | E5: =RAND() -> 0.051605211 | F5: 130000 | G5: =(C5*1000)*F5 -> 22909900000 | H5: 37 | I5: 17000 | J5: =H5*C5 -> 6520.51 | K5: =J5*I5 -> 1.1084867e+08 | L5: =G5-K5 -> 22799051330
A6: Daging Kambing | B6: SULAWESI SELATAN | C6: 881 | D6: 2022 | E6: =RAND() -> 0.20903582 | F6: 130000 | G6: =(C6*1000)*F6 -> 114530000000 | H6: 37 | I6: 17000 | J6: =H6*C6 -> 32597 | K6: =J6*I6 -> 554149000 | L6: =G6-K6 -> 113975851000
A7: Daging Sapi | B7: JAWA TIMUR | C7: 108284.07 | D7: 2021 | E7: =RAND() -> 0.9734554 | F7: 150000 | G7: =(C7*1000)*F7 -> 16242610500000 | H7: 39 | I7: 17800 | J7: =H7*C7 -> 4223078.7 | K7: =J7*I7 -> 7.5170801e+10 | L7: =G7-K7 -> 16167439698606
A8: Daging Sapi | B8: JAWA TENGAH | C8: 61393.95 | D8: 2022 | E8: =RAND() -> 0.12280765 | F8: 150000 | G8: =(C8*1000)*F8 -> 9209092500000 | H8: 40 | I8: 17800 | J8: =H8*C8 -> 2455758 | K8: =J8*I8 -> 43712492400 | L8: =G8-K8 -> 9165380007600
A9: Daging Sapi | B9: PAPUA BARAT | C9: 1506.02 | D9: 2022 | E9: =RAND() -> 0.76046258 | F9: 150000 | G9: =(C9*1000)*F9 -> 225903000000 | H9: 40 | I9: 17800 | J9: =H9*C9 -> 60240.8 | K9: =J9*I9 -> 1072286240 | L9: =G9-K9 -> 224830713760
A10: Daging Sapi | B10: JAWA BARAT | C10: 78134.54 | D10: 2021 | E10: =RAND() -> 0.66970792 | F10: 150000 | G10: =(C10*1000)*F10 -> 11720181000000 | H10: 39 | I10: 17800 | J10: =H10*C10 -> 3047247.1 | K10: =J10*I10 -> 5.4240998e+10 | L10: =G10-K10 -> 11665940002332
A11: Daging Domba | B11: SULAWESI TENGGARA | C11: 0 | D11: 2022 | E11: =RAND() -> 0.93104135 | F11: 68000 | G11: =(C11*1000)*F11 -> 0 | H11: 28 | I11: 18000 | J11: =H11*C11 -> 0 | K11: =J11*I11 -> 0 | L11: =G11-K11 -> 0
A12: Daging Kambing | B12: SUMATERA UTARA | C12: 848.87 | D12: 2020 | E12: =RAND() -> 0.2980213 | F12: 130000 | G12: =(C12*1000)*F12 -> 110353100000 | H12: 35 | I12: 17000 | J12: =H12*C12 -> 29710.45 | K12: =J12*I12 -> 505077650 | L12: =G12-K12 -> 109848022350
A13: Daging Ayam | B13: KEP. BANGKA BELITUNG | C13: 27037.46 | D13: 2021 | E13: =RAND() -> 0.95868804 | F13: 34000 | G13: =(C13*1000)*F13 -> 919273640000 | H13: 21 | I13: 9000 | J13: =H13*C13 -> 567786.66 | K13: =J13*I13 -> 5110079940 | L13: =G13-K13 -> 914163560060
A14: Daging Ayam | B14: MALUKU UTARA | C14: 37.09 | D14: 2021 | E14: =RAND() -> 0.64514575 | F14: 34000 | G14: =(C14*1000)*F14 -> 1261060000 | H14: 21 | I14: 9000 | J14: =H14*C14 -> 778.89 | K14: =J14*I14 -> 7010010 | L14: =G14-K14 -> 1254049990
... A512: Daging Domba | B512: SUMATERA UTARA | C512: 499.33 | D512: 2020 | E512: =RAND() -> 0.4165125 | F512: 68000 | G512: =(C512*1000)*F512 -> 33954440000 | H512: 31 | I512: 18000 | J512: =H512*C512 -> 15479.23 | K512: =J512*I512 -> 278626140 | L512: =G512-K512 -> 33675813860

Sheet Data Visualization
A1: Mencari total produksi berdasarkan produk
A2: Produk | B2: Sub Total
A3: Daging Ayam | B3: =SUMIF('Main Data'!$A$3:$A$512,'Data Visualization'!A3,'Main Data'!$C$3:$C$512) -> 15863907
A4: Daging Domba | B4: =SUMIF('Main Data'!$A$3:$A$512,'Data Visualization'!A4,'Main Data'!$C$3:$C$512) -> 159541.05
A5: Daging Itik | B5: =SUMIF('Main Data'!$A$3:$A$512,'Data Visualization'!A5,'Main Data'!$C$3:$C$512) -> 1048954.8
A6: Daging Kambing | B6: =SUMIF('Main Data'!$A$3:$A$512,'Data Visualization'!A6,'Main Data'!$C$3:$C$512) -> 185099.78
A7: Daging Sapi | B7: =SUMIF('Main Data'!$A$3:$A$512,'Data Visualization'!A7,'Main Data'!$C$3:$C$512) -> 1440143.8
A9: Mencari total produksi Daging Sapi setiap tahun
A10: Tahun | B10: Sub Total
A11: 2020 | B11: =SUMIFS('Main Data'!$C$3:$C$512,'Main Data'!$D$3:$D$512,'Data Visualization'!A11,'Main Data'!$A$3:$A$512,"Daging Sapi") -> 453418.45
A12: 2021 | B12: =SUMIFS('Main Data'!$C$3:$C$512,'Main Data'!$D$3:$D$512,'Data Visualization'!A12,'Main Data'!$A$3:$A$512,"Daging Sapi") -> 487802.2
A13: 2022 | B13: =SUMIFS('Main Data'!$C$3:$C$512,'Main Data'!$D$3:$D$512,'Data Visualization'!A13,'Main Data'!$A$3:$A$512,"Daging Sapi") -> 498923.17
A15: Mencari total produksi Daging Ayam di Papua tahun 2022
A16: Tahun | B16: Total produksi
A17: Papua | B17: =SUMIFS('Main Data'!$C$3:$C$512,'Main Data'!$B$3:$B$512,'Data Visualization'!A17,'Main Data'!$A$3:$A$512,"Daging Ayam",'Main Data'!$D$3:$D$512,2022) -> 15843.11
A18: Papua Barat | B18: =SUMIFS('Main Data'!$C$3:$C$512,'Main Data'!$B$3:$B$512,'Data Visualization'!A18,'Main Data'!$A$3:$A$512,"Daging Ayam",'Main Data'!$D$3:$D$512,2022) -> 9648.27
A20: Mencari Total Pengeluaran Pakan Ternak
A21: Tahun | B21: Banyak pakan | C21: Total Pengeluaran
A22: 2020 | B22: =SUMIF('Main Data'!$D$3:$D$512,'Data Visualization'!A22,'Main Data'!$J$3:$J$512) -> 1.5903992e+08 | C22: =SUMIF('Main Data'!$D$3:$D$512,'Data Visualization'!A22,'Main Data'!$K$3:$K$512) -> 1622924959340
A23: 2021 | B23: =SUMIF('Main Data'!$D$3:$D$512,'Data Visualization'!A23,'Main Data'!$J$3:$J$512) -> 1.3984099e+08 | C23: =SUMIF('Main Data'!$D$3:$D$512,'Data Visualization'!A23,'Main Data'!$K$3:$K$512) -> 1463497059500
A24: 2022 | B24: =SUMIF('Main Data'!$D$3:$D$512,'Data Visualization'!A24,'Main Data'!$J$3:$J$512) -> 1.4546972e+08 | C24: =SUMIF('Main Data'!$D$3:$D$512,'Data Visualization'!A24,'Main Data'!$K$3:$K$512) -> 1525703575478
A26: Mencari total produksi berdasarkan Daging Sapi di Pulau Jawa berdasarkan tahun
A27: Tahun | B27: Sub Total (Provinsi)
B28: Banten | C28: DKI Jakarta | D28: Jawa Barat | E28: Jawa Tengah | F28: DI Yogyakarta | G28: Jawa Timur
A29: 2020 | B29: =SUMIFS('Main Data'!$C$3:$C$512,'Main Data'!$D$3:$D$512,'Data Visualization'!$A29,'Main Data'!$B$3:$B$512,'Data Visualization'!B$28) -> 283640.8 | C29: =SUMIFS('Main Data'!$C$3:$C$512,'Main Data'!$D$3:$D$512,'Data Visualization'!$A29,'Main Data'!$B$3:$B$512,'Data Visualization'!C$28) -> 8156.18 | D29: =SUMIFS('Main Data'!$C$3:$C$512,'Main Data'!$D$3:$D$512,'Data Visualization'!$A29,'Main Data'!$B$3:$B$512,'Data Visualization'!D$28) -> 780722.32 | E29: =SUMIFS('Main Data'!$C$3:$C$512,'Main Data'!$D$3:$D$512,'Data Visualization'!$A29,'Main Data'!$B$3:$B$512,'Data Visualization'!E$28) -> 778285.37 | F29: =SUMIFS('Main Data'!$C$3:$C$512,'Main Data'!$D$3:$D$512,'Data Visualization'!$A29,'Main Data'!$B$3:$B$512,'Data Visualization'!F$28) -> 122188.23 | G29: =SUMIFS('Main Data'!$C$3:$C$512,'Main Data'!$D$3:$D$512,'Data Visualization'!$A29,'Main Data'!$B$3:$B$512,'Data Visualization'!G$28) -> 1784296.2
A30: 2021 | B30: =SUMIFS('Main Data'!$C$3:$C$512,'Main Data'!$D$3:$D$512,'Data Visualization'!$A30,'Main Data'!$B$3:$B$512,'Data Visualization'!B$28) -> 268691.66 | C30: =SUMIFS('Main Data'!$C$3:$C$512,'Main Data'!$D$3:$D$512,'Data Visualization'!$A30,'Main Data'!$B$3:$B$512,'Data Visualization'!C$28) -> 17285.42 | D30: =SUMIFS('Main Data'!$C$3:$C$512,'Main Data'!$D$3:$D$512,'Data Visualization'!$A30,'Main Data'!$B$3:$B$512,'Data Visualization'!D$28) -> 842494.06 | E30: =SUMIFS('Main Data'!$C$3:$C$512,'Main Data'!$D$3:$D$512,'Data Visualization'!$A30,'Main Data'!$B$3:$B$512,'Data Visualization'!E$28) -> 852197.62 | F30: =SUMIFS('Main Data'!$C$3:$C$512,'Main Data'!$D$3:$D$512,'Data Visualization'!$A30,'Main Data'!$B$3:$B$512,'Data Visualization'!F$28) -> 144368.85 | G30: =SUMIFS('Main Data'!$C$3:$C$512,'Main Data'!$D$3:$D$512,'Data Visualization'!$A30,'Main Data'!$B$3:$B$512,'Data Visualization'!G$28) -> 1657427.8
A31: 2022 | B31: =SUMIFS('Main Data'!$C$3:$C$512,'Main Data'!$D$3:$D$512,'Data Visualization'!$A31,'Main Data'!$B$3:$B$512,'Data Visualization'!B$28) -> 352269.55 | C31: =SUMIFS('Main Data'!$C$3:$C$512,'Main Data'!$D$3:$D$512,'Data Visualization'!$A31,'Main Data'!$B$3:$B$512,'Data Visualization'!C$28) -> 18610.07 | D31: =SUMIFS('Main Data'!$C$3:$C$512,'Main Data'!$D$3:$D$512,'Data Visualization'!$A31,'Main Data'!$B$3:$B$512,'Data Visualization'!D$28) -> 892191.81 | E31: =SUMIFS('Main Data'!$C$3:$C$512,'Main Data'!$D$3:$D$512,'Data Visualization'!$A31,'Main Data'!$B$3:$B$512,'Data Visualization'!E$28) -> 944922.64 | F31: =SUMIFS('Main Data'!$C$3:$C$512,'Main Data'!$D$3:$D$512,'Data Visualization'!$A31,'Main Data'!$B$3:$B$512,'Data Visualization'!F$28) -> 182982.44 | G31: =SUMIFS('Main Data'!$C$3:$C$512,'Main Data'!$D$3:$D$512,'Data Visualization'!$A31,'Main Data'!$B$3:$B$512,'Data Visualization'!G$28) -> 1500053.9
A34: Produksi daging sapi per provinsi tahun 2022
A35: Provinsi | B35: Jumlah produksi
A36: JAWA TIMUR | B36: =SUMIFS('Main Data'!$C$3:$C$512,'Main Data'!$D$3:$D$512,2022,'Main Data'!$A$3:$A$512,"Daging Sapi",'Main Data'!$B$3:$B$512,'Data Visualization'!A36) -> 110991.18
A37: GORONTALO | B37: =SUMIFS('Main Data'!$C$3:$C$512,'Main Data'!$D$3:$D$512,2022,'Main Data'!$A$3:$A$512,"Daging Sapi",'Main Data'!$B$3:$B$512,'Data Visualization'!A37) -> 2918.75
A38: BENGKULU | B38: =SUMIFS('Main Data'!$C$3:$C$512,'Main Data'!$D$3:$D$512,2022,'Main Data'!$A$3:$A$512,"Daging Sapi",'Main Data'!$B$3:$B$512,'Data Visualization'!A38) -> 3329.27
A39: SULAWESI SELATAN | B39: =SUMIFS('Main Data'!$C$3:$C$512,'Main Data'!$D$3:$D$512,2022,'Main Data'!$A$3:$A$512,"Daging Sapi",'Main Data'!$B$3:$B$512,'Data Visualization'!A39) -> 16277.51
A40: JAWA TENGAH | B40: =SUMIFS('Main Data'!$C$3:$C$512,'Main Data'!$D$3:$D$512,2022,'Main Data'!$A$3:$A$512,"Daging Sapi",'Main Data'!$B$3:$B$512,'Data Visualization'!A40) -> 61393.95
A41: PAPUA BARAT | B41: =SUMIFS('Main Data'!$C$3:$C$512,'Main Data'!$D$3:$D$512,2022,'Main Data'!$A$3:$A$512,"Daging Sapi",'Main Data'!$B$3:$B$512,'Data Visualization'!A41) -> 1506.02
A42: JAWA BARAT | B42: =SUMIFS('Main Data'!$C$3:$C$512,'Main Data'!$D$3:$D$512,2022,'Main Data'!$A$3:$A$512,"Daging Sapi",'Main Data'!$B$3:$B$512,'Data Visualization'!A42) -> 84960.62
A43: SULAWESI TENGGARA | B43: =SUMIFS('Main Data'!$C$3:$C$512,'Main Data'!$D$3:$D$512,2022,'Main Data'!$A$3:$A$512,"Daging Sapi",'Main Data'!$B$3:$B$512,'Data Visualization'!A43) -> 4525.62
A44: SUMATERA UTARA | B44: =SUMIFS('Main Data'!$C$3:$C$512,'Main Data'!$D$3:$D$512,2022,'Main Data'!$A$3:$A$512,"Daging Sapi",'Main Data'!$B$3:$B$512,'Data Visualization'!A44) -> 13859.09
A45: KEP. BANGKA BELITUNG | B45: =SUMIFS('Main Data'!$C$3:$C$512,'Main Data'!$D$3:$D$512,2022,'Main Data'!$A$3:$A$512,"Daging Sapi",'Main Data'!$B$3:$B$512,'Data Visualization'!A45) -> 3395.04
A46: MALUKU UTARA | B46: =SUMIFS('Main Data'!$C$3:$C$512,'Main Data'!$D$3:$D$512,2022,'Main Data'!$A$3:$A$512,"Daging Sapi",'Main Data'!$B$3:$B$512,'Data Visualization'!A46) -> 1320.51
...
